{
    "parts": [
        {
            "x": -1,
            "y": 0,
            "z": 0,
            "elements": [
                "jaopca:block_sheetmetalstainlesssteel@0"
            ]
        },
        {
            "x": -3,
            "y": 0,
            "z": 4,
            "elements": [
                "jaopca:block_sheetmetalstainlesssteel@0"
            ]
        },
        {
            "x": -2,
            "y": 2,
            "z": 5,
            "elements": [
                "jaopca:block_sheetmetalstainlesssteel@0"
            ]
        },
        {
            "x": -1,
            "y": 4,
            "z": 6,
            "elements": [
                "jaopca:block_sheetmetalstainlesssteel@0"
            ]
        },
        {
            "x": 3,
            "y": 4,
            "z": 2,
            "elements": [
                "jaopca:block_sheetmetalstainlesssteel@0"
            ]
        },
        {
            "x": 2,
            "y": 2,
            "z": 1,
            "elements": [
                "jaopca:block_sheetmetalstainlesssteel@0"
            ]
        },
        {
            "x": 1,
            "y": 0,
            "z": 0,
            "elements": [
                "jaopca:block_sheetmetalstainlesssteel@0"
            ]
        },
        {
            "x": 0,
            "y": 4,
            "z": 6,
            "nbt": {"input":"1b","size":"1","casingColor":"15119454","ForgeCaps":{"nuclearcraft:capability_default_radiation_resistance":{"shieldingRadResistance":"0.0d","radiationResistance":"0.0d"}},"id":"minecraft:tilefluidinputhatch","tank":{"Empty":"","gasTag":{"Empty":""}}},
            "elements": [
                "modularmachinery:blockfluidinputhatch@1"
            ]
        },
        {
            "x": 1,
            "y": 4,
            "z": 6,
            "elements": [
                "jaopca:block_sheetmetalstainlesssteel@0"
            ]
        },
        {
            "x": 2,
            "y": 2,
            "z": 5,
            "elements": [
                "jaopca:block_sheetmetalstainlesssteel@0"
            ]
        },
        {
            "x": 3,
            "y": 0,
            "z": 4,
            "elements": [
                "jaopca:block_sheetmetalstainlesssteel@0"
            ]
        },
        {
            "x": -2,
            "y": 3,
            "z": 1,
            "elements": [
                "jaopca:block_sheetmetalstainlesssteel@0"
            ]
        },
        {
            "x": 0,
            "y": 5,
            "z": 2,
            "elements": [
                "contenttweaker:invar_scaffolding@0"
            ]
        },
        {
            "x": 0,
            "y": 3,
            "z": 1,
            "elements": [
                "chisel:tyrian@15"
            ]
        },
        {
            "x": -1,
            "y": 1,
            "z": 0,
            "elements": [
                "jaopca:block_sheetmetalstainlesssteel@0"
            ]
        },
        {
            "x": 0,
            "y": 1,
            "z": 0,
            "nbt": {"busSize":"1","casingColor":"15119454","ForgeCaps":{"nuclearcraft:capability_default_radiation_resistance":{"shieldingRadResistance":"0.0d","radiationResistance":"0.0d"}},"id":"minecraft:tileiteminputbus","inventory":{"inventoryArray":[{"holderEmpty":"1b","holderId":"0"},{"holderEmpty":"1b","holderId":"1"},{"holderEmpty":"1b","holderId":"2"},{"holderEmpty":"1b","holderId":"3"}],"outSlots":,"miscSlots":,"inSlots":,"sides":}},
            "elements": [
                "modularmachinery:blockinputbus@1"
            ]
        },
        {
            "x": -3,
            "y": 1,
            "z": 4,
            "elements": [
                "jaopca:block_sheetmetalstainlesssteel@0"
            ]
        },
        {
            "x": -2,
            "y": 3,
            "z": 5,
            "elements": [
                "jaopca:block_sheetmetalstainlesssteel@0"
            ]
        },
        {
            "x": 2,
            "y": 3,
            "z": 1,
            "elements": [
                "jaopca:block_sheetmetalstainlesssteel@0"
            ]
        },
        {
            "x": 1,
            "y": 1,
            "z": 0,
            "elements": [
                "jaopca:block_sheetmetalstainlesssteel@0"
            ]
        },
        {
            "x": 0,
            "y": 5,
            "z": 6,
            "elements": [
                "contenttweaker:invar_scaffolding@0"
            ]
        },
        {
            "x": 0,
            "y": 3,
            "z": 5,
            "elements": [
                "chisel:tyrian@15"
            ]
        },
        {
            "x": -2,
            "y": -1,
            "z": 3,
            "elements": [
                "jaopca:block_sheetmetalstainlesssteel@0"
            ]
        },
        {
            "x": -1,
            "y": -1,
            "z": 3,
            "elements": [
                "jaopca:block_sheetmetalstainlesssteel@0"
            ]
        },
        {
            "x": 0,
            "y": -1,
            "z": 3,
            "elements": [
                "jaopca:block_sheetmetalstainlesssteel@0"
            ]
        },
        {
            "x": 2,
            "y": 3,
            "z": 5,
            "elements": [
                "jaopca:block_sheetmetalstainlesssteel@0"
            ]
        },
        {
            "x": 1,
            "y": -1,
            "z": 3,
            "elements": [
                "jaopca:block_sheetmetalstainlesssteel@0"
            ]
        },
        {
            "x": 3,
            "y": 1,
            "z": 4,
            "elements": [
                "jaopca:block_sheetmetalstainlesssteel@0"
            ]
        },
        {
            "x": 2,
            "y": -1,
            "z": 3,
            "elements": [
                "jaopca:block_sheetmetalstainlesssteel@0"
            ]
        },
        {
            "x": -2,
            "y": 4,
            "z": 1,
            "elements": [
                "jaopca:block_sheetmetalstainlesssteel@0"
            ]
        },
        {
            "x": -1,
            "y": 2,
            "z": 0,
            "elements": [
                "jaopca:block_sheetmetalstainlesssteel@0"
            ]
        },
        {
            "x": 0,
            "y": 2,
            "z": 0,
            "elements": [
                "jaopca:block_sheetmetalstainlesssteel@0"
            ]
        },
        {
            "x": -3,
            "y": 2,
            "z": 4,
            "elements": [
                "jaopca:block_sheetmetalstainlesssteel@0"
            ]
        },
        {
            "x": -2,
            "y": 4,
            "z": 5,
            "elements": [
                "jaopca:block_sheetmetalstainlesssteel@0"
            ]
        },
        {
            "x": 2,
            "y": 4,
            "z": 1,
            "elements": [
                "jaopca:block_sheetmetalstainlesssteel@0"
            ]
        },
        {
            "x": 1,
            "y": 2,
            "z": 0,
            "elements": [
                "jaopca:block_sheetmetalstainlesssteel@0"
            ]
        },
        {
            "x": -3,
            "y": 0,
            "z": 3,
            "elements": [
                "jaopca:block_sheetmetalstainlesssteel@0"
            ]
        },
        {
            "x": -2,
            "y": 0,
            "z": 3,
            "elements": [
                "chisel:tyrian@15"
            ]
        },
        {
            "x": -1,
            "y": 0,
            "z": 3,
            "elements": [
                "chisel:tyrian@15"
            ]
        },
        {
            "x": 0,
            "y": 0,
            "z": 3,
            "elements": [
                "chisel:laboratory@11"
            ]
        },
        {
            "x": 2,
            "y": 4,
            "z": 5,
            "elements": [
                "jaopca:block_sheetmetalstainlesssteel@0"
            ]
        },
        {
            "x": 1,
            "y": 0,
            "z": 3,
            "elements": [
                "chisel:tyrian@15"
            ]
        },
        {
            "x": 3,
            "y": 2,
            "z": 4,
            "elements": [
                "jaopca:block_sheetmetalstainlesssteel@0"
            ]
        },
        {
            "x": 2,
            "y": 0,
            "z": 3,
            "elements": [
                "chisel:tyrian@15"
            ]
        },
        {
            "x": 3,
            "y": 0,
            "z": 3,
            "elements": [
                "jaopca:block_sheetmetalstainlesssteel@0"
            ]
        },
        {
            "x": -1,
            "y": 3,
            "z": 0,
            "elements": [
                "jaopca:block_sheetmetalstainlesssteel@0"
            ]
        },
        {
            "x": 0,
            "y": 5,
            "z": 1,
            "elements": [
                "contenttweaker:invar_scaffolding@0"
            ]
        },
        {
            "x": 0,
            "y": 3,
            "z": 0,
            "elements": [
                "jaopca:block_sheetmetalstainlesssteel@0"
            ]
        },
        {
            "x": 1,
            "y": 3,
            "z": 0,
            "elements": [
                "jaopca:block_sheetmetalstainlesssteel@0"
            ]
        },
        {
            "x": -3,
            "y": 3,
            "z": 4,
            "elements": [
                "jaopca:block_sheetmetalstainlesssteel@0"
            ]
        },
        {
            "x": -3,
            "y": 1,
            "z": 3,
            "elements": [
                "jaopca:block_sheetmetalstainlesssteel@0"
            ]
        },
        {
            "x": 0,
            "y": 5,
            "z": 5,
            "elements": [
                "contenttweaker:invar_scaffolding@0"
            ]
        },
        {
            "x": 0,
            "y": 3,
            "z": 4,
            "elements": [
                "chisel:tyrian@15"
            ]
        },
        {
            "x": -2,
            "y": -1,
            "z": 2,
            "elements": [
                "jaopca:block_sheetmetalstainlesssteel@0"
            ]
        },
        {
            "x": 0,
            "y": 1,
            "z": 3,
            "elements": [
                "chisel:laboratory@11"
            ]
        },
        {
            "x": -1,
            "y": -1,
            "z": 2,
            "elements": [
                "jaopca:block_sheetmetalstainlesssteel@0"
            ]
        },
        {
            "x": 0,
            "y": -1,
            "z": 2,
            "elements": [
                "jaopca:block_sheetmetalstainlesssteel@0"
            ]
        },
        {
            "x": 3,
            "y": 3,
            "z": 4,
            "elements": [
                "jaopca:block_sheetmetalstainlesssteel@0"
            ]
        },
        {
            "x": 1,
            "y": -1,
            "z": 2,
            "elements": [
                "jaopca:block_sheetmetalstainlesssteel@0"
            ]
        },
        {
            "x": 3,
            "y": 1,
            "z": 3,
            "elements": [
                "jaopca:block_sheetmetalstainlesssteel@0"
            ]
        },
        {
            "x": 2,
            "y": -1,
            "z": 2,
            "elements": [
                "jaopca:block_sheetmetalstainlesssteel@0"
            ]
        },
        {
            "x": -1,
            "y": 4,
            "z": 0,
            "elements": [
                "jaopca:block_sheetmetalstainlesssteel@0"
            ]
        },
        {
            "x": 0,
            "y": 4,
            "z": 0,
            "nbt": {"input":"1b","size":"1","casingColor":"15119454","ForgeCaps":{"nuclearcraft:capability_default_radiation_resistance":{"shieldingRadResistance":"0.0d","radiationResistance":"0.0d"}},"id":"minecraft:tilefluidinputhatch","tank":{"Empty":"","gasTag":{"Empty":""}}},
            "elements": [
                "modularmachinery:blockfluidinputhatch@1"
            ]
        },
        {
            "x": 1,
            "y": 4,
            "z": 0,
            "elements": [
                "jaopca:block_sheetmetalstainlesssteel@0"
            ]
        },
        {
            "x": -3,
            "y": 4,
            "z": 4,
            "elements": [
                "jaopca:block_sheetmetalstainlesssteel@0"
            ]
        },
        {
            "x": -3,
            "y": 2,
            "z": 3,
            "elements": [
                "jaopca:block_sheetmetalstainlesssteel@0"
            ]
        },
        {
            "x": -3,
            "y": 0,
            "z": 2,
            "elements": [
                "jaopca:block_sheetmetalstainlesssteel@0"
            ]
        },
        {
            "x": 0,
            "y": 2,
            "z": 3,
            "elements": [
                "chisel:laboratory@11"
            ]
        },
        {
            "x": 3,
            "y": 4,
            "z": 4,
            "elements": [
                "jaopca:block_sheetmetalstainlesssteel@0"
            ]
        },
        {
            "x": 3,
            "y": 2,
            "z": 3,
            "elements": [
                "jaopca:block_sheetmetalstainlesssteel@0"
            ]
        },
        {
            "x": 3,
            "y": 0,
            "z": 2,
            "elements": [
                "jaopca:block_sheetmetalstainlesssteel@0"
            ]
        },
        {
            "x": -1,
            "y": 0,
            "z": 6,
            "elements": [
                "jaopca:block_sheetmetalstainlesssteel@0"
            ]
        },
        {
            "x": 0,
            "y": 0,
            "z": 6,
            "elements": [
                "jaopca:block_sheetmetalstainlesssteel@0"
            ]
        },
        {
            "x": 1,
            "y": 0,
            "z": 6,
            "elements": [
                "jaopca:block_sheetmetalstainlesssteel@0"
            ]
        },
        {
            "x": 0,
            "y": 5,
            "z": 0,
            "elements": [
                "contenttweaker:invar_scaffolding@0"
            ]
        },
        {
            "x": -3,
            "y": 3,
            "z": 3,
            "elements": [
                "jaopca:block_sheetmetalstainlesssteel@0"
            ]
        },
        {
            "x": -3,
            "y": 1,
            "z": 2,
            "elements": [
                "jaopca:block_sheetmetalstainlesssteel@0"
            ]
        },
        {
            "x": 0,
            "y": 5,
            "z": 4,
            "elements": [
                "contenttweaker:invar_scaffolding@0"
            ]
        },
        {
            "x": 0,
            "y": 3,
            "z": 3,
            "elements": [
                "chisel:laboratory@11"
            ]
        },
        {
            "x": -1,
            "y": -1,
            "z": 1,
            "elements": [
                "jaopca:block_sheetmetalstainlesssteel@0"
            ]
        },
        {
            "x": 0,
            "y": -1,
            "z": 1,
            "elements": [
                "jaopca:block_sheetmetalstainlesssteel@0"
            ]
        },
        {
            "x": 3,
            "y": 3,
            "z": 3,
            "elements": [
                "jaopca:block_sheetmetalstainlesssteel@0"
            ]
        },
        {
            "x": 1,
            "y": -1,
            "z": 1,
            "elements": [
                "jaopca:block_sheetmetalstainlesssteel@0"
            ]
        },
        {
            "x": 3,
            "y": 1,
            "z": 2,
            "elements": [
                "jaopca:block_sheetmetalstainlesssteel@0"
            ]
        },
        {
            "x": -1,
            "y": 1,
            "z": 6,
            "elements": [
                "jaopca:block_sheetmetalstainlesssteel@0"
            ]
        },
        {
            "x": 0,
            "y": 1,
            "z": 6,
            "elements": [
                "jaopca:block_sheetmetalstainlesssteel@0"
            ]
        },
        {
            "x": -1,
            "y": -1,
            "z": 5,
            "elements": [
                "jaopca:block_sheetmetalstainlesssteel@0"
            ]
        },
        {
            "x": 0,
            "y": -1,
            "z": 5,
            "elements": [
                "jaopca:block_sheetmetalstainlesssteel@0"
            ]
        },
        {
            "x": 1,
            "y": 1,
            "z": 6,
            "elements": [
                "jaopca:block_sheetmetalstainlesssteel@0"
            ]
        },
        {
            "x": 1,
            "y": -1,
            "z": 5,
            "elements": [
                "jaopca:block_sheetmetalstainlesssteel@0"
            ]
        },
        {
            "x": -3,
            "y": 4,
            "z": 3,
            "nbt": {"input":"1b","size":"1","casingColor":"15119454","ForgeCaps":{"nuclearcraft:capability_default_radiation_resistance":{"shieldingRadResistance":"0.0d","radiationResistance":"0.0d"}},"id":"minecraft:tilefluidinputhatch","tank":{"Empty":"","gasTag":{"Empty":""}}},
            "elements": [
                "modularmachinery:blockfluidinputhatch@1"
            ]
        },
        {
            "x": -3,
            "y": 2,
            "z": 2,
            "elements": [
                "jaopca:block_sheetmetalstainlesssteel@0"
            ]
        },
        {
            "x": 0,
            "y": 4,
            "z": 3,
            "elements": [
                "chisel:laboratory@11"
            ]
        },
        {
            "x": -2,
            "y": 0,
            "z": 1,
            "elements": [
                "jaopca:block_sheetmetalstainlesssteel@0"
            ]
        },
        {
            "x": 3,
            "y": 4,
            "z": 3,
            "nbt": {"input":"1b","size":"1","casingColor":"15119454","ForgeCaps":{"nuclearcraft:capability_default_radiation_resistance":{"shieldingRadResistance":"0.0d","radiationResistance":"0.0d"}},"id":"minecraft:tilefluidinputhatch","tank":{"Empty":"","gasTag":{"Empty":""}}},
            "elements": [
                "modularmachinery:blockfluidinputhatch@1"
            ]
        },
        {
            "x": 3,
            "y": 2,
            "z": 2,
            "elements": [
                "jaopca:block_sheetmetalstainlesssteel@0"
            ]
        },
        {
            "x": 2,
            "y": 0,
            "z": 1,
            "elements": [
                "jaopca:block_sheetmetalstainlesssteel@0"
            ]
        },
        {
            "x": -2,
            "y": 0,
            "z": 5,
            "elements": [
                "jaopca:block_sheetmetalstainlesssteel@0"
            ]
        },
        {
            "x": -1,
            "y": 2,
            "z": 6,
            "elements": [
                "jaopca:block_sheetmetalstainlesssteel@0"
            ]
        },
        {
            "x": 0,
            "y": 2,
            "z": 6,
            "elements": [
                "jaopca:block_sheetmetalstainlesssteel@0"
            ]
        },
        {
            "x": 1,
            "y": 2,
            "z": 6,
            "elements": [
                "jaopca:block_sheetmetalstainlesssteel@0"
            ]
        },
        {
            "x": 2,
            "y": 0,
            "z": 5,
            "elements": [
                "jaopca:block_sheetmetalstainlesssteel@0"
            ]
        },
        {
            "x": -3,
            "y": 5,
            "z": 3,
            "elements": [
                "contenttweaker:invar_scaffolding@0"
            ]
        },
        {
            "x": -3,
            "y": 3,
            "z": 2,
            "elements": [
                "jaopca:block_sheetmetalstainlesssteel@0"
            ]
        },
        {
            "x": -2,
            "y": 5,
            "z": 3,
            "elements": [
                "contenttweaker:invar_scaffolding@0"
            ]
        },
        {
            "x": -1,
            "y": 5,
            "z": 3,
            "elements": [
                "contenttweaker:invar_scaffolding@0"
            ]
        },
        {
            "x": -2,
            "y": 1,
            "z": 1,
            "elements": [
                "jaopca:block_sheetmetalstainlesssteel@0"
            ]
        },
        {
            "x": 0,
            "y": 5,
            "z": 3,
            "nbt": {"hatchSize":"1","casingColor":"15119454","ForgeCaps":{"nuclearcraft:capability_default_radiation_resistance":{"shieldingRadResistance":"0.0d","radiationResistance":"0.0d"}},"id":"minecraft:tileenergyinputhatch","energy":"0L"},
            "elements": [
                "modularmachinery:blockenergyinputhatch@1"
            ]
        },
        {
            "x": 1,
            "y": 5,
            "z": 3,
            "elements": [
                "contenttweaker:invar_scaffolding@0"
            ]
        },
        {
            "x": 0,
            "y": 3,
            "z": 2,
            "elements": [
                "chisel:tyrian@15"
            ]
        },
        {
            "x": 2,
            "y": 5,
            "z": 3,
            "elements": [
                "contenttweaker:invar_scaffolding@0"
            ]
        },
        {
            "x": 3,
            "y": 5,
            "z": 3,
            "elements": [
                "contenttweaker:invar_scaffolding@0"
            ]
        },
        {
            "x": -2,
            "y": 1,
            "z": 5,
            "elements": [
                "jaopca:block_sheetmetalstainlesssteel@0"
            ]
        },
        {
            "x": -1,
            "y": 3,
            "z": 6,
            "elements": [
                "jaopca:block_sheetmetalstainlesssteel@0"
            ]
        },
        {
            "x": 3,
            "y": 3,
            "z": 2,
            "elements": [
                "jaopca:block_sheetmetalstainlesssteel@0"
            ]
        },
        {
            "x": 2,
            "y": 1,
            "z": 1,
            "elements": [
                "jaopca:block_sheetmetalstainlesssteel@0"
            ]
        },
        {
            "x": 0,
            "y": 3,
            "z": 6,
            "elements": [
                "jaopca:block_sheetmetalstainlesssteel@0"
            ]
        },
        {
            "x": -2,
            "y": -1,
            "z": 4,
            "elements": [
                "jaopca:block_sheetmetalstainlesssteel@0"
            ]
        },
        {
            "x": 1,
            "y": 3,
            "z": 6,
            "elements": [
                "jaopca:block_sheetmetalstainlesssteel@0"
            ]
        },
        {
            "x": -1,
            "y": -1,
            "z": 4,
            "elements": [
                "jaopca:block_sheetmetalstainlesssteel@0"
            ]
        },
        {
            "x": 0,
            "y": -1,
            "z": 4,
            "elements": [
                "jaopca:block_sheetmetalstainlesssteel@0"
            ]
        },
        {
            "x": 2,
            "y": 1,
            "z": 5,
            "elements": [
                "jaopca:block_sheetmetalstainlesssteel@0"
            ]
        },
        {
            "x": 1,
            "y": -1,
            "z": 4,
            "elements": [
                "jaopca:block_sheetmetalstainlesssteel@0"
            ]
        },
        {
            "x": 2,
            "y": -1,
            "z": 4,
            "elements": [
                "jaopca:block_sheetmetalstainlesssteel@0"
            ]
        },
        {
            "x": -3,
            "y": 4,
            "z": 2,
            "elements": [
                "jaopca:block_sheetmetalstainlesssteel@0"
            ]
        },
        {
            "x": -2,
            "y": 2,
            "z": 1,
            "elements": [
                "jaopca:block_sheetmetalstainlesssteel@0"
            ]
        }
    ]}