{
    "registryname": "minifield-crafter",
    "localizedname": "3D Crafter",
        "parts": [
            {
                "x": 0,
                "y": 1,
                "z": 8,
                "elements": [
                    "fieldprojector"
                ]
            },
            {
                "x": 4,
                "y": 1,
                "z": 4,
                "elements": [
                    "fieldprojector"
                ]
            },
            {
                "x": 0,
                "y": 1,
                "z": 0,
                "elements": [
                    "fieldprojector"
                ]
            },
            {
                "x": -4,
                "y": 1,
                "z": 4,
                "elements": [
                    "fieldprojector"
                ]
            },
            {
                "x": -4,
                "y": 0,
                "z": 4,
                "elements": [
                    "casings_item"
                ]
            },
            
        {
            "x": 1,
            "y": 4,
            "z": 3,
            "elements": [
                "actuallyadditions:block_misc@8"
            ]
        },
        {
            "x": 0,
            "y": 4,
            "z": 4,
            "elements": [
                "actuallyadditions:block_misc@8"
            ]
        },
        {
            "x": -1,
            "y": 4,
            "z": 5,
            "elements": [
                "actuallyadditions:block_misc@8"
            ]
        },
        {
            "x": 1,
            "y": 4,
            "z": 4,
            "elements": [
                "actuallyadditions:block_misc@8"
            ]
        },
        {
            "x": 0,
            "y": 4,
            "z": 5,
            "elements": [
                "actuallyadditions:block_misc@8"
            ]
        },
        {
            "x": 1,
            "y": 4,
            "z": 5,
            "elements": [
                "actuallyadditions:block_misc@8"
            ]
        },
        {
            "x": -1,
            "y": 4,
            "z": 3,
            "elements": [
                "actuallyadditions:block_misc@8"
            ]
        },
        {
            "x": 0,
            "y": 4,
            "z": 3,
            "elements": [
                "actuallyadditions:block_misc@8"
            ]
        },
        {
            "x": -1,
            "y": 4,
            "z": 4,
            "elements": [
                "actuallyadditions:block_misc@8"
            ]
        },
        {
            "x": 2,
            "y": 4,
            "z": 5,
            "elements": [
                "modularmachinery:blockcasing@1"
            ]
        },
        {
            "x": -1,
            "y": 4,
            "z": 2,
            "elements": [
                "modularmachinery:blockcasing@1"
            ]
        },
        {
            "x": 0,
            "y": 4,
            "z": 2,
             "elements": [
                "modularmachinery:blockcasing@1"
            ]
        },
        {
            "x": 1,
            "y": 4,
            "z": 2,
            "elements": [
                "modularmachinery:blockcasing@1"
            ]
        },
            {
                "x": -3,
                "y": 2,
                "z": 5,
                "elements": [
                    "thermalfoundation:glass_alloy@7"
                ]
            },
            {
                "x": -2,
                "y": 4,
                "z": 6,
                "elements": [
                    "modularmachinery:blockcasing@1"
                ]
            },
            {
                "x": 2,
                "y": 4,
                "z": 2,
                "elements": [
                    "modularmachinery:blockcasing@1"
                ]
            },
            {
                "x": 1,
                "y": 2,
                "z": 1,
                "elements": [
                    "thermalfoundation:glass_alloy@7"
                ]
            },
            {
                "x": -3,
                "y": 0,
                "z": 4,
                "elements": [
                    "modularmachinery:blockcasing@0"
                ]
            },
            {
                "x": -1,
                "y": 4,
                "z": 6,
                "elements": [
                    "modularmachinery:blockcasing@1"
                ]
            },
            {
                "x": 2,
                "y": 2,
                "z": 1,
                "elements": [
                    "thermalfoundation:glass_alloy@7"
                ]
            },
            {
                "x": 0,
                "y": 4,
                "z": 6,
                "elements": [
                    "modularmachinery:blockcasing@1"
                ]
            },
            {
                "x": 1,
                "y": 4,
                "z": 6,
                "elements": [
                    "modularmachinery:blockcasing@1"
                ]
            },
            {
                "x": 2,
                "y": 4,
                "z": 6,
                "elements": [
                    "modularmachinery:blockcasing@1"
                ]
            },
            {
                "x": 3,
                "y": 2,
                "z": 5,
                "elements": [
                    "thermalfoundation:glass_alloy@7"
                ]
            },
            {
                "x": 3,
                "y": 0,
                "z": 4,
                "elements": [
                    "modularmachinery:blockcasing@0"
                ]
            },
            {
                "x": 4,
                "y": 0,
                "z": 4,
                "elements": [
                    "casings_item"
                ]
            },
            {
                "x": 0,
                "y": 0,
                "z": 8,
                "elements": [
                    "modularmachinery:blockenergyinputhatch"
                ]
            },
            {
                "x": -2,
                "y": 3,
                "z": 1,
                "elements": [
                    "modularmachinery:blockcasing@0"
                ]
            },
            {
                "x": -1,
                "y": 3,
                "z": 1,
                "elements": [
                    "modularmachinery:blockcasing@0"
                ]
            },
            {
                "x": 0,
                "y": 3,
                "z": 1,
                "elements": [
                    "modularmachinery:blockcasing@0"
                ]
            },
            {
                "x": 1,
                "y": 3,
                "z": 1,
                "elements": [
                    "modularmachinery:blockcasing@0"
                ]
            },

            {
                "x": -3,
                "y": 3,
                "z": 5,
                "elements": [
                    "modularmachinery:blockcasing@0"
                ]
            },
            {
                "x": -3,
                "y": 1,
                "z": 4,
                "elements": [
                    "thermalfoundation:glass_alloy@7"
                ]
            },
            {
                "x": 2,
                "y": 3,
                "z": 1,
                "elements": [
                    "modularmachinery:blockcasing@0"
                ]
            },
            {
                "x": 3,
                "y": 3,
                "z": 5,
                "elements": [
                    "modularmachinery:blockcasing@0"
                ]
            },
            {
                "x": 3,
                "y": 1,
                "z": 4,
                "elements": [
                    "thermalfoundation:glass_alloy@7"
                ]
            },
            {
                "x": -3,
                "y": 2,
                "z": 4,
                "elements": [
                    "thermalfoundation:glass_alloy@7"
                ]
            },
            {
                "x": -2,
                "y": 4,
                "z": 5,
                "elements": [
                    "modularmachinery:blockcasing@1"
                ]
            },
            {
                "x": -3,
                "y": 0,
                "z": 3,
                "elements": [
                    "modularmachinery:blockcasing@0"
                ]
            },
            {
                "x": 3,
                "y": 2,
                "z": 4,
                "elements": [
                    "thermalfoundation:glass_alloy@7"
                ]
            },
            {
                "x": -2,
                "y": 0,
                "z": 7,
                "elements": [
                    "modularmachinery:blockcasing@0"
                ]
            },
            {
                "x": 3,
                "y": 0,
                "z": 3,
                "elements": [
                    "modularmachinery:blockcasing@0"
                ]
            },
            {
                "x": -1,
                "y": 0,
                "z": 7,
                "elements": [
                    "modularmachinery:blockcasing@0"
                ]
            },
            {
                "x": 0,
                "y": 0,
                "z": 7,
                "elements": [
                    "modularmachinery:blockcasing@0"
                ]
            },
            {
                "x": 1,
                "y": 0,
                "z": 7,
                "elements": [
                    "modularmachinery:blockcasing@0"
                ]
            },
            {
                "x": 2,
                "y": 0,
                "z": 7,
                "elements": [
                    "modularmachinery:blockcasing@0"
                ]
            },
            {
                "x": -3,
                "y": 3,
                "z": 4,
                "elements": [
                    "modularmachinery:blockcasing@0"
                ]
            },
            {
                "x": -3,
                "y": 1,
                "z": 3,
                "elements": [
                    "thermalfoundation:glass_alloy@7"
                ]
            },
            {
                "x": -2,
                "y": 1,
                "z": 7,
                "elements": [
                    "thermalfoundation:glass_alloy@7"
                ]
            },
            {
                "x": 3,
                "y": 3,
                "z": 4,
                "elements": [
                    "modularmachinery:blockcasing@0"
                ]
            },
            {
                "x": 3,
                "y": 1,
                "z": 3,
                "elements": [
                    "thermalfoundation:glass_alloy@7"
                ]
            },
            {
                "x": -1,
                "y": 1,
                "z": 7,
                "elements": [
                    "thermalfoundation:glass_alloy@7"
                ]
            },
            {
                "x": 0,
                "y": 1,
                "z": 7,
                "elements": [
                    "thermalfoundation:glass_alloy@7"
                ]
            },
            {
                "x": 1,
                "y": 1,
                "z": 7,
                "elements": [
                    "thermalfoundation:glass_alloy@7"
                ]
            },
            {
                "x": 2,
                "y": 1,
                "z": 7,
                "elements": [
                    "thermalfoundation:glass_alloy@7"
                ]
            },
            {
                "x": -3,
                "y": 2,
                "z": 3,
                "elements": [
                    "thermalfoundation:glass_alloy@7"
                ]
            },
            {
                "x": -2,
                "y": 4,
                "z": 4,
                "elements": [
                    "modularmachinery:blockcasing@1"
                ]
            },
            {
                "x": -3,
                "y": 0,
                "z": 2,
                "elements": [
                    "modularmachinery:blockcasing@0"
                ]
            },
            {
                "x": 2,
                "y": 4,
                "z": 4,
                "elements": [
                    "modularmachinery:blockcasing@1"
                ]
            },
            {
                "x": -3,
                "y": 0,
                "z": 6,
                "elements": [
                    "modularmachinery:blockcasing@0"
                ]
            },
            {
                "x": -2,
                "y": 2,
                "z": 7,
                "elements": [
                    "thermalfoundation:glass_alloy@7"
                ]
            },
            {
                "x": 3,
                "y": 2,
                "z": 3,
                "elements": [
                    "thermalfoundation:glass_alloy@7"
                ]
            },
            {
                "x": -1,
                "y": 2,
                "z": 7,
                "elements": [
                    "thermalfoundation:glass_alloy@7"
                ]
            },
            {
                "x": 0,
                "y": 2,
                "z": 7,
                "elements": [
                    "thermalfoundation:glass_alloy@7"
                ]
            },
            {
                "x": 3,
                "y": 0,
                "z": 2,
                "elements": [
                    "modularmachinery:blockcasing@0"
                ]
            },
            {
                "x": 1,
                "y": 2,
                "z": 7,
                "elements": [
                    "thermalfoundation:glass_alloy@7"
                ]
            },
            {
                "x": 2,
                "y": 2,
                "z": 7,
                "elements": [
                    "thermalfoundation:glass_alloy@7"
                ]
            },
            {
                "x": 3,
                "y": 0,
                "z": 6,
                "elements": [
                    "modularmachinery:blockcasing@0"
                ]
            },
            {
                "x": -3,
                "y": 3,
                "z": 3,
                "elements": [
                    "modularmachinery:blockcasing@0"
                ]
            },
            {
                "x": -3,
                "y": 1,
                "z": 2,
                "elements": [
                    "thermalfoundation:glass_alloy@7"
                ]
            },
            {
                "x": -3,
                "y": 1,
                "z": 6,
                "elements": [
                    "thermalfoundation:glass_alloy@7"
                ]
            },
            {
                "x": -2,
                "y": 3,
                "z": 7,
                "elements": [
                    "modularmachinery:blockcasing@0"
                ]
            },
            {
                "x": -1,
                "y": 3,
                "z": 7,
                "elements": [
                    "modularmachinery:blockcasing@0"
                ]
            },
            {
                "x": 3,
                "y": 3,
                "z": 3,
                "elements": [
                    "modularmachinery:blockcasing@0"
                ]
            },
            {
                "x": 0,
                "y": 3,
                "z": 7,
                "elements": [
                    "modularmachinery:blockcasing@0"
                ]
            },
            {
                "x": 3,
                "y": 1,
                "z": 2,
                "elements": [
                    "thermalfoundation:glass_alloy@7"
                ]
            },
            {
                "x": 1,
                "y": 3,
                "z": 7,
                "elements": [
                    "modularmachinery:blockcasing@0"
                ]
            },
            {
                "x": 2,
                "y": 3,
                "z": 7,
                "elements": [
                    "modularmachinery:blockcasing@0"
                ]
            },
            {
                "x": 3,
                "y": 1,
                "z": 6,
                "elements": [
                    "thermalfoundation:glass_alloy@7"
                ]
            },
            {
                "x": -3,
                "y": 2,
                "z": 2,
                "elements": [
                    "thermalfoundation:glass_alloy@7"
                ]
            },
            {
                "x": -2,
                "y": 4,
                "z": 3,
                "elements": [
                    "modularmachinery:blockcasing@1"
                ]
            },
            {
                "x": -2,
                "y": 0,
                "z": 1,
                "elements": [
                    "modularmachinery:blockcasing@0"
                ]
            },
            {
                "x": -1,
                "y": 0,
                "z": 1,
                "elements": [
                    "modularmachinery:blockcasing@0"
                ]
            },
            {
                "x": 0,
                "y": 0,
                "z": 1,
                "elements": [
                    "modularmachinery:blockcasing@0"
                ]
            },
            {
                "x": -3,
                "y": 2,
                "z": 6,
                "elements": [
                    "thermalfoundation:glass_alloy@7"
                ]
            },
            {
                "x": 2,
                "y": 4,
                "z": 3,
                "elements": [
                    "modularmachinery:blockcasing@1"
                ]
            },
            {
                "x": -3,
                "y": 0,
                "z": 5,
                "elements": [
                    "modularmachinery:blockcasing@0"
                ]
            },
            {
                "x": 1,
                "y": 0,
                "z": 1,
                "elements": [
                    "modularmachinery:blockcasing@0"
                ]
            },
            {
                "x": 3,
                "y": 2,
                "z": 2,
                "elements": [
                    "thermalfoundation:glass_alloy@7"
                ]
            },
            {
                "x": 2,
                "y": 0,
                "z": 1,
                "elements": [
                    "modularmachinery:blockcasing@0"
                ]
            },
            {
                "x": 3,
                "y": 2,
                "z": 6,
                "elements": [
                    "thermalfoundation:glass_alloy@7"
                ]
            },
            {
                "x": 3,
                "y": 0,
                "z": 5,
                "elements": [
                    "modularmachinery:blockcasing@0"
                ]
            },
            {
                "x": -3,
                "y": 3,
                "z": 2,
                "elements": [
                    "modularmachinery:blockcasing@0"
                ]
            },
            {
                "x": -2,
                "y": 1,
                "z": 1,
                "elements": [
                    "thermalfoundation:glass_alloy@7"
                ]
            },
            {
                "x": -1,
                "y": 1,
                "z": 1,
                "elements": [
                    "thermalfoundation:glass_alloy@7"
                ]
            },
            {
                "x": 0,
                "y": 1,
                "z": 1,
                "elements": [
                    "thermalfoundation:glass_alloy@7"
                ]
            },
            {
                "x": -3,
                "y": 3,
                "z": 6,
                "elements": [
                    "modularmachinery:blockcasing@0"
                ]
            },
            {
                "x": -3,
                "y": 1,
                "z": 5,
                "elements": [
                    "thermalfoundation:glass_alloy@7"
                ]
            },
            {
                "x": 1,
                "y": 1,
                "z": 1,
                "elements": [
                    "thermalfoundation:glass_alloy@7"
                ]
            },
            {
                "x": 3,
                "y": 3,
                "z": 2,
                "elements": [
                    "modularmachinery:blockcasing@0"
                ]
            },
            {
                "x": 2,
                "y": 1,
                "z": 1,
                "elements": [
                    "thermalfoundation:glass_alloy@7"
                ]
            },
            {
                "x": 3,
                "y": 3,
                "z": 6,
                "elements": [
                    "modularmachinery:blockcasing@0"
                ]
            },
            {
                "x": 3,
                "y": 1,
                "z": 5,
                "elements": [
                    "thermalfoundation:glass_alloy@7"
                ]
            },
            {
                "x": -2,
                "y": 4,
                "z": 2,
                "elements": [
                    "modularmachinery:blockcasing@1"
                ]
            },
            {
                "x": -2,
                "y": 2,
                "z": 1,
                "elements": [
                    "thermalfoundation:glass_alloy@7"
                ]
            },

            {
                "x": -1,
                "y": 2,
                "z": 1,
                "elements": [
                    "thermalfoundation:glass_alloy@7"
                ]
            },
            {
                "x": 0,
                "y": 2,
                "z": 1,
                "elements": [
                    "thermalfoundation:glass_alloy@7"
                ]
            }
        ]}